<?xml version="1.0" ?>
<robot name="omo_r1" xmlns:xacro="http://ros.org/wiki/xacro">
  <xacro:include filename="$(find omo_r1_description)/urdf/common_properties.xacro"/>
  

	
  <link name="map"/>

  <joint name="m2odom" type="fixed">
    <parent link="map"/>
    <child link="odom" />
    <origin xyz="0 0 0" rpy="0 0 0.0"/>
  </joint>

  <link name="odom"/>

  <joint name="o2bf" type="fixed">
    <parent link="odom"/>
    <child link="base_footprint" />
    <origin xyz="0 0.0 0" rpy="0 0 0.0"/>
  </joint>

  <link name="base_footprint"/>

  <joint name="base_joint" type="fixed">
    <parent link="base_footprint"/>
    <child link="base_link" />
    <origin xyz="0 0.0 0.15" rpy="0 0 0.0"/>
  </joint>

  <link name="base_link">
    <visual>
      <!--origin xyz="0 0.276 0.19" rpy="0 0 0"/!-->
      <origin xyz="-0.07 0.181 -0.11" rpy="0 0 0"/>
      <geometry>
        <mesh filename="package://omo_r1_description/meshes/body.stl" scale="0.018 0.018 0.018"/>
      </geometry>
      <material name="light_black"/>
    </visual>

    <collision>
      <origin xyz="-0.07 0.181 -0.11" rpy="3.14 0 -1.57"/>
      <geometry>
        <mesh filename="package://omo_r1_description/meshes/body.stl" scale="0.018 0.018 0.018"/>
      </geometry>
    </collision>

    <inertial>
      <origin xyz="-0.028 0 0" rpy="0 0 0"/>
      <mass value="8.2573504"/>
      <inertia ixx="2.2124416e-02" ixy="-1.2294101e-04" ixz="3.4938785e-04"
               iyy="2.1193702e-02" iyz="-5.0120904e-05"
               izz="2.0064271e-02" />
    </inertial>
  
  </link>

  <joint name="wheel_left_joint" type="continuous">
    <parent link="base_link"/>
    <child link="wheel_left_link"/>
    <!--origin xyz="0.0 0.275 0.037" rpy="0.0 0.0 0"/!-->
    <origin xyz="0.0 0.085 -0.015" rpy="0.0 0.0 0"/>
    <axis xyz="0 1 0"/>
  </joint>

  <link name="wheel_left_link">
    <visual>
	<origin xyz="-0.275 0.04 -0.15" rpy="0 0 0"/>
	<geometry>
	    <mesh filename="package://omo_r1_description/meshes/left_wheel2.stl" scale="0.018 0.018 0.018"/>
	</geometry>
	<material name="black"/>
    </visual>

  <collision>
    <origin xyz="-0.275 0.04 -0.15" rpy="0 0 0"/>
    <geometry>
      <mesh filename="package://omo_r1_description/meshes/left_wheel2.stl" scale="0.018 0.018 0.018"/>
    </geometry>
  </collision>
  <inertial>
    <origin xyz="0 0 0" rpy="0 0 0"/>
    <mass value="1.5"/>
    <inertia ixx="0.002" ixy="0" ixz="0"
             iyy="0.002" iyz="0"
             izz="0.001"/>
  </inertial>
  </link>

  <joint name="wheel_right_joint" type="continuous">
    <parent link="base_link"/>
    <child link="wheel_right_link"/>
    <!--origin xyz="0.0 -0.275 0.037" rpy="0.0 0 0"/!-->
    <origin xyz="0.0 -0.085 -0.015" rpy="0.0 0 0"/>
    <axis xyz="0 1 0"/>
  </joint>

  <link name="wheel_right_link">
    <visual>
        <origin xyz="-0.087 0.32 -0.15" rpy="0 0 0"/>
        <geometry>
            <mesh filename="package://omo_r1_description/meshes/right_wheel2.stl" scale="0.018 0.018 0.018"/>
        </geometry>
        <material name="black"/>
    </visual>

    <collision>
        <origin xyz="-0.087 0.32 -0.15" rpy="0 0 0"/>
        <geometry>
            <mesh filename="package://omo_r1_description/meshes/right_wheel2.stl" scale="0.018 0.018 0.018"/>
        </geometry>
    </collision>
    <inertial>
        <origin xyz="0 0 0" rpy="0 0 0"/>
        <mass value="1.5"/>
        <inertia ixx="0.002" ixy="0" ixz="0"
                 iyy="0.002" iyz="0"
                 izz="0.001"/>
    </inertial>
  </link>

  <joint name="imu_joint" type="fixed">
    <parent link="base_link"/>
    <child link="imu_link"/>
    <origin xyz="0.0 0 0.190" rpy="0 0 1.5758"/>
  </joint>

  <link name="imu_link"/>

  <joint name="scan_joint" type="fixed">
    <parent link="base_link"/>
    <child link="base_scan"/>
    <origin xyz="0.06 0 0.230" rpy="0.0 0.0 0.0"/>
  </joint>

  <link name="base_scan">
    
  </link>

  
</robot>
